<mujoco model="left_clamp_arm">
  <compiler angle="radian" meshdir="assets"/>

  <option integrator="implicitfast" cone="elliptic" impratio="10"/>

  <default>
    <default class="left_clamp_arm">
      <joint armature="0.5" frictionloss="0.2"/>
      <position kp="30" kv="5" forcerange="-87 87" inheritrange="1"/>
      <default class="visual">
        <geom type="mesh" group="2" contype="0" conaffinity="0"/>
      </default>
      <default class="collision">
        <geom type="mesh" group="3" mass="0" density="0"/>
        <default class="pad_box1">
          <geom type="box" friction="0.7" solimp="0.95 0.99 0.001" solref="0.004 1" mass="0" priority="1"
            size="0.002 0.002 0.0025" rgba="0.2 0.2 0.2 1"/>
        </default>
        <default class="pad_box2">
          <geom type="box" friction="0.6" solimp="0.95 0.99 0.001" solref="0.004 1" mass="0" priority="1"
            size="0.002 0.002 0.0052" rgba="0.1 0.1 0.1 1"/>
        </default>
        <default class="driver">
        <joint range="0 0.8" armature="0.005" damping="0.1" solimplimit="0.95 0.99 0.001" solreflimit="0.005 1"/>
      </default>
      <default class="follower">
        <joint range="-0.872664 0.872664" armature="0.001" pos="0 -0.018 0.0065" solimplimit="0.95 0.99 0.001" solreflimit="0.005 1"/>
      </default>
      <default class="pivot_link">
        <joint range="-0.29670597283 0.8" armature="0.001" stiffness="0.05" springref="2.62" damping="0.00125"/>
      </default>
      <default class="coupler">
        <joint range="-1.57 0" armature="0.001" solimplimit="0.95 0.99 0.001" solreflimit="0.005 1"/>
      </default>

      </default>
    </default>
  </default>

  <asset>
    <material name="black" rgba="0.1 0.1 0.1 1"/>
    <material name="white" rgba="0.8 0.8 0.8 1"/>

    <mesh name="base_link" file="base_link.STL"/>
    <mesh name="shoulder_motor_link" file="shoulder_motor_link.STL"/>
    <mesh name="shoulder_link" file="shoulder_link.STL"/>
    <mesh name="deltoid_motor_link" file="deltoid_motor_link.STL"/>
    <mesh name="deltoid_link" file="deltoid_link.STL"/>
    <mesh name="forearm_link" file="forearm_link.STL"/>
    <mesh name="forearm_motor_link" file="forearm_motor_link.STL"/>
    <mesh name="wrist_link" file="wrist_link.STL"/>
    <mesh name="wrist_motor_link" file="wrist_motor_link.STL"/>
    <mesh name="main_gear_link" file="main_gear_link.STL"/>
    <mesh name="clamp_gear_1_link" file="clamp_gear_1_link.STL"/>
    <mesh name="clamp_gear_2_link" file="clamp_gear_2_link.STL"/>
     <mesh name="pivot_3_link" file="pivot_3_link.STL"/>
    <mesh name="pivot_2_link" file="pivot_2_link.STL"/>
    <mesh name="pivot_1_link" file="pivot_1_link.STL"/>
    <mesh name="pivot_4_link" file="pivot_4_link.STL"/>
    <!-- Collision meshes -->
    <mesh name="base_link_collision" file="base_link.STL"/>
    <mesh name="shoulder_motor_link_collision" file="shoulder_motor_link.STL"/>
    <mesh name="shoulder_link_collision" file="shoulder_link.STL"/>
    <mesh name="deltoid_motor_link_collision" file="deltoid_motor_link.STL"/>
    <mesh name="deltoid_link_collision" file="deltoid_link.STL"/>
    <mesh name="forearm_link_collision" file="forearm_link.STL"/>
    <mesh name="forearm_motor_link_collision" file="forearm_motor_link.STL"/>
    <mesh name="wrist_link_collision" file="wrist_link.STL"/>
    <mesh name="wrist_motor_link_collision" file="wrist_motor_link.STL"/>
    <mesh name="main_gear_link_collision" file="main_gear_link.STL"/>
    <mesh name="clamp_gear_1_link_collision" file="clamp_gear_1_link.STL"/>
   </asset>
  <worldbody>
    <body name="base_link" childclass="left_clamp_arm" pos="0 0 0.3">
    <geom mesh="base_link" class="visual" material="white"/>
   <geom mesh="base_link_collision" class="collision"/>

    <body name="shoulder_motor_link" pos="0.02505 -3.1519E-05 0.040139">
    <inertial pos="0.011924 -0.00048792 0.013381" quat="-0.0190903 0.705417 0.0178052 0.708312" mass="0.05"
    diaginertia="1.44921e-05 1.2371e-05 7.59138e-06"/>
    <joint name="shoulder_motor_joint" pos="0 0 0" axis="0 0 -1" range="-2.2 2.2"/>
    <geom mesh="shoulder_motor_link" class="visual" material="black"/>
    <!--<geom mesh="shoulder_motor_link_collision" class="collision"/> -->

    <body name="shoulder_link" pos="0 0 0">
    <inertial pos="0.0133776171428082 0.0123058890407129 0.0167881487228331" quat="-0.0190903 0.705417 0.0178052 0.708312" mass="0.05"
    diaginertia="1.44921e-05 1.2371e-05 7.59138e-06"/>
    <joint name="shoulder_joint" pos="0 0 0" axis="0 0 -1" range="-2.2 2.2"/>
    <geom mesh="shoulder_link" class="visual" material="white"/>
    <geom mesh="shoulder_link_collision" class="collision"/>

    <body name="deltoid_motor_link" pos="0.0012519 -0.016837 -0.080078" euler="0.0010742 0.0069315 0.12341">
    <inertial pos="0.011924 -0.00048792 0.013381" quat="-0.0190903 0.705417 0.0178052 0.708312" mass="0.5"
    diaginertia="1.44921e-05 1.2371e-05 7.59138e-06"/>
    <joint name="deltoid_motor_joint" pos="0 0 0" axis="0 0 -1" range="-2.2 2.2"/>
    <geom mesh="deltoid_motor_link" class="visual" material="black"/>
    <!--<geom mesh="deltoid_motor_link_collision" class="collision"/> -->

    <body name="deltoid_link" pos="0 0 0">
    <inertial pos="0.0133776171428082 0.0123058890407129 0.0167881487228331" quat="-0.0190903 0.705417 0.0178052 0.708312" mass="0.05"
    diaginertia="1.44921e-05 1.2371e-05 7.59138e-06"/>
    <joint name="deltoid_joint" pos="0 0 0" axis="0 1 0" range="-0.200 2.2"/>
    <geom mesh="deltoid_link" class="visual" material="white"/>
    <geom mesh="deltoid_link_collision" class="collision"/>

    <body name="forearm_motor_link" pos="0.128104821087058 -0.000722801873955833 0.0654655508370285" euler="-0.00447925955028608 -0.474038024854068 0.00108929805000388">
    <inertial pos="0.011924 -0.00048792 0.013381" quat="-0.0190903 0.705417 0.0178052 0.708312" mass="0.05"
    diaginertia="1.44921e-05 1.2371e-05 7.59138e-06"/>
    <joint name="forearm_motor_joint" pos="0 0 0" axis="0 0 -1" range="-2.2 2.2"/>
    <geom mesh="forearm_motor_link" class="visual" material="black"/>
    <!--<geom mesh="forearm_motor_link_collision" class="collision"/> -->

    <body name="forearm_link" pos="0 0 0">
    <inertial pos="0.0133776171428082 0.0123058890407129 0.0167881487228331" quat="-0.0190903 0.705417 0.0178052 0.708312" mass="0.05"
    diaginertia="1.44921e-05 1.2371e-05 7.59138e-06"/>
    <joint name="forearm_joint" pos="0 0 0" axis="0 1 0" range="-2.2 2.2"/>
    <geom mesh="forearm_link" class="visual" material="white"/>
    <geom mesh="forearm_link_collision" class="collision"/>

    <body name="wrist_motor_link" pos="0.112516470710041 -0.000589104990071289 -0.0896482204395607" euler="-0.00181602262765292 0.671097523978476 0.0024046179049158">
    <inertial pos="0.011924 -0.00048792 0.013381" quat="-0.0190903 0.705417 0.0178052 0.708312" mass="0.05"
    diaginertia="1.44921e-05 1.2371e-05 7.59138e-06"/>
    <joint name="wrist_motor_joint" pos="0 0 0" axis="0 0 -1" range="-2.2 2.2"/>
    <geom mesh="wrist_motor_link" class="visual" material="black"/>
    <!--<geom mesh="wrist_motor_link_collision" class="collision"/> -->

    <body name="wrist_link" pos="0 0 0">
    <inertial pos="0.0133776171428082 0.0123058890407129 0.0167881487228331" quat="-0.0190903 0.705417 0.0178052 0.708312" mass="0.05"
    diaginertia="1.44921e-05 1.2371e-05 7.59138e-06"/>
    <joint name="wrist_joint" pos="0 0 0" axis="0 1 0" range="-2.2 2.2"/>
    <geom mesh="wrist_link" class="visual" material="white"/>
    <geom mesh="wrist_link_collision" class="collision"/>

     <body name="main_gear_link" pos="0.166590198981601 0.0277949892185482 0.0673832956014138" euler="0.0100065342380608 -0.51136660021399 -0.0136239739409153">
    <inertial pos="0.0133776171428082 0.0123058890407129 0.0167881487228331" quat="-0.0190903 0.705417 0.0178052 0.708312" mass="0.05"
    diaginertia="1.44921e-05 1.2371e-05 7.59138e-06"/>
    <joint name="main_gear_joint" pos="0 0 0" axis="0 0 1" range="-2.2 2.2"/>
    <geom mesh="main_gear_link" class="visual" material="white"/>
    <!--<geom mesh="main_gear_link_collision" class="collision"/>-->

    <body name="clamp_gear_1_link" pos="0.0209247165550157 -0.00198460205949517 -0.00100000000003472" euler="0 0 0">
        <inertial pos="0.0133776171428082 0.0123058890407129 0.0167881487228331" quat="-0.0190903 0.705417 0.0178052 0.708312" mass="0.05"
        diaginertia="1.44921e-05 1.2371e-05 7.59138e-06"/>
        <joint name="clamp_gear1_joint" pos="0 0 0" axis="0 0 1" range="-2.2 2.2"/>
        <geom mesh="clamp_gear_1_link" class="visual" material="white"/>
        <!--<geom mesh="clamp_gear_1_link_collision" class="collision"/>-->
        <body name="pivot_3_link" pos="0.0371454613116111 0.0220557250405514 0.00440000000003429">
        <inertial pos="0.0133776171428082 0.0123058890407129 0.0167881487228331" quat="-0.0190903 0.705417 0.0178052 0.708312" mass="0.05"
        diaginertia="1.44921e-05 1.2371e-05 7.59138e-06"/>
            <joint name="pivot_3_joint" pos="0 0 0" axis="0 0 1" range="-2.2 2.2"/>
            <geom class="visual" mesh="pivot_3_link" material="black"/>
            <geom class="collision" mesh="pivot_3_link"/>
          <body name="pivot_2_link" pos="-0.0209999999999966 0.0210000000000035 0.00600000000000149">
                <inertial mass="0.0125222" pos="0 -0.011046 0.0124786" quat="1 0.1664 0 0"
                diaginertia="2.67415e-06 2.4559e-06 6.02031e-07"/>
                <joint name="pivot_2_joint" class="follower"/>
                <geom class="visual" mesh="pivot_2_link" material="black"/>
                <!--<geom class="collision" mesh="pivot_2_link"/>-->
          <body name="pivot_1_link" pos="-0.0371454592044878 -0.0220557217176893 0">
                    <inertial mass="0.0125222" pos="0 -0.011046 0.0124786" quat="1 0.1664 0 0"
                    diaginertia="2.67415e-06 2.4559e-06 6.02031e-07"/>
                    <joint name="pivot_1_joint" class="follower"/>
                    <geom class="visual" mesh="pivot_1_link" material="black"/>
                    <!--<geom class="collision" mesh="pivot_1_link"/>-->
        </body>
        </body>
        </body>
      
        
      </body>

    </body>
    </body>
    </body>
    </body>
    </body>
    </body>
    </body>
    </body>
    </body>
    </body>
  </worldbody>
  <!-- Actuator definitions-->
  <actuator>
    <position class="left_clamp_arm" name="shoulder" joint="shoulder_joint" forcerange="-87 87"/>
    <position class="left_clamp_arm" name="deltoid" joint="deltoid_joint" forcerange="-87 87"/>
    <position class="left_clamp_arm" name="forearm" joint="forearm_joint" forcerange="-87 87"/>
    <position class="left_clamp_arm" name="wrist" joint="wrist_joint" forcerange="-87 87"/>

  </actuator>

  <contact>
    <exclude name="exclude_base_shoulder" body1="base_link" body2="shoulder_link"/>
    <exclude name="exclude_shoulder_deltoid" body1="shoulder_link" body2="deltoid_link"/>
    <exclude name="exclude_deltoid_forearm" body1="deltoid_link" body2="forearm_link"/>
    <exclude name="exclude_forearm_wrist" body1="forearm_link" body2="wrist_link"/>
    <exclude name="exclude_wrist_main_gear" body1="wrist_link" body2="main_gear_link"/>
    <exclude name="exclude_main_gear_clamp_gear1" body1="main_gear_link" body2="clamp_gear_1_link"/>
    <exclude name="exclude_wrist_pivot" body1="wrist_link" body2="pivot_1_link"/>
    <exclude name="exclude_wrist_pivot2" body1="wrist_link" body2="pivot_2_link"/>
    <exclude name="exclude_pivot_links" body1="pivot_1_link" body2="pivot_2_link"/>
    <exclude name="exclude_pivot_links_2" body1="pivot_2_link" body2="pivot_3_link"/>
    <!--<exclude name="exclude_clamp_gear1_clamp_gear2" body1="clamp_gear_1_link" body2="clamp_gear_2_link"/>
    <exclude name="exclude_clamp_gear2_pivot" body1="clamp_gear_2_link" body2="pivot_3_link"/>-->


  </contact>


  <keyframe>
    <key name="home" qpos="0" ctrl="0"/>
  </keyframe>
</mujoco>
